<?xml version="1.0"?>
<robot xmlns:xacro="http://www.ros.org/wiki/xacro" name="genesis_robot">

    <!-- Gazebo Plugin -->
    <gazebo>
        <plugin filename="ign_ros2_control-system" name="ign_ros2_control::IgnitionROS2ControlPlugin">
            <robot_param>robot_description</robot_param>
            <robot_param_node>robot_state_publisher</robot_param_node>
            <parameters>$(find genesis_robot_description)/config/genesis_robot.yaml</parameters>
        </plugin>
    </gazebo>

    <xacro:property name="M_PI" value="3.14159274"/>

    <!-- Materials -->
    <material name="gray">
        <color rgba="0.5 0.5 0.5 1.0"/>
    </material>
    <material name="white">
        <color rgba="1.0 1.0 1.0 1.0"/>
    </material>
    <material name="black">
        <color rgba="0 0 0 1.0"/>
    </material>

    <!-- Base Link -->
    <link name="base_footprint"/>

    <joint name="base_link_joint" type="fixed">
        <origin xyz="0 0 0"/>
        <parent link="base_footprint"/>
        <child link="base_link"/>
    </joint>

    <link name="base_link">
        <visual>
            <origin xyz="0 0 0" rpy="0 0 0"/>
            <geometry>
                <box size="2.0 1.2 0.2"/> <!-- Box of size 2.0m x 1.2m x 0.2m -->
            </geometry>
            <material name="gray"/>
        </visual>
        <collision>
            <origin xyz="0 0 0" rpy="0 0 0"/>
            <geometry>
                <box size="2.0 1.2 0.2"/> <!-- Box of size 2.0m x 1.2m x 0.2m -->
            </geometry>
        </collision>
        <inertial>
            <origin xyz="0 0 0.1"/>
            <mass value="10.0"/>
            <inertia ixx="1.0" ixy="0" ixz="0" iyy="1.0" iyz="0" izz="1.0" />
        </inertial>
    </link>

    <!-- Suspension Macro -->
    <xacro:macro name="steering_v0" params="prefix parent *joint_origin *joint_axis">
        <joint name="${prefix}_steering_joint" type="revolute">
            <xacro:insert_block name="joint_origin"/>
            <parent link="${parent}"/>
            <child link="${prefix}_steering_link"/>
            <limit effort="5" velocity="6.28" lower="-2.1" upper="2.1" />
            <xacro:insert_block name="joint_axis"/>
        </joint>

        <link name="${prefix}_steering_link">
            <visual>
                <origin xyz="0 0 0" rpy="0 0 0"/>
                <geometry>
                    <cylinder length="0.1" radius="0.05"/>
                </geometry>
                <material name="gray"/>
            </visual>
            <collision>
                <origin xyz="0 0 0" rpy="0 0 0"/>
                <geometry>
                    <cylinder length="0.1" radius="0.05"/>
                </geometry>
            </collision>
            <inertial>
                <origin xyz="0 0 -0.02"/>
                <mass value="0.15"/>
                <inertia ixx="0.00001" ixy="0" ixz="0" iyy="0.00001" iyz="0" izz="0.000004" />
            </inertial>
        </link>
    </xacro:macro>

    <!-- Wheel Macro -->
    <xacro:macro name="wheel_v0" params="prefix parent *joint_origin *joint_axis">
        <joint name="${prefix}_wheel_joint" type="continuous">
            <xacro:insert_block name="joint_origin"/>
            <parent link="${parent}"/>
            <child link="${prefix}_wheel_link"/>
            <limit effort="1.5" velocity="20"/>
            <xacro:insert_block name="joint_axis"/>
        </joint>

        <link name="${prefix}_wheel_link">
            <visual>
                <origin xyz="0 0 0" rpy="1.5708 0 0"/>
                <geometry>
                    <cylinder length="0.25" radius="0.3"/> <!-- Wheel of radius 0.3m -->
                </geometry>
                <material name="black"/>
            </visual>
            <collision>
                <origin xyz="0 0 0" rpy="1.5708 0 0"/>
                <geometry>
                    <cylinder length="0.25" radius="0.3"/> <!-- Wheel of radius 0.3m -->
                </geometry>
            </collision>
            <inertial>
                <origin xyz="0 0 0"/>
                <mass value="1.0"/>
                <inertia ixx="0.1" ixy="0" ixz="0" iyy="0.1" iyz="0" izz="0.1"/>
            </inertial>
        </link>
    </xacro:macro>

    <!-- Front Right Suspension -->
    <xacro:steering_v0 prefix="fr" parent="base_link">
        <origin xyz="1.0 -0.6 0"/>
        <axis xyz="0 0 1"/>
    </xacro:steering_v0>
    <xacro:wheel_v0 prefix="fr" parent="fr_steering_link">
        <origin xyz="0 0 0" rpy="0 0 0"/>
        <axis xyz="0 1 0"/>
    </xacro:wheel_v0>

    <!-- Front Left Suspension -->
    <xacro:steering_v0 prefix="fl" parent="base_link">
        <origin xyz="1.0 0.6 0"/>
        <axis xyz="0 0 1"/>
    </xacro:steering_v0>
    <xacro:wheel_v0 prefix="fl" parent="fl_steering_link">
        <origin xyz="0 0 0" rpy="0 0 0"/>
        <axis xyz="0 1 0"/>
    </xacro:wheel_v0>

    <!-- Rear Right Wheel -->
    <xacro:wheel_v0 prefix="rr" parent="base_link">
        <origin xyz="-1.0 -0.6 0" rpy="0 0 0"/>
        <axis xyz="0 1 0"/>
    </xacro:wheel_v0>

    <!-- Rear Left Wheel -->
    <xacro:wheel_v0 prefix="rl" parent="base_link">
        <origin xyz="-1.0 0.6 0" rpy="0 0 0"/>
        <axis xyz="0 1 0"/>
    </xacro:wheel_v0>

    <!-- ros2_control -->
    <ros2_control name="IgnitionSystem" type="system">
        <hardware>
            <plugin>ign_ros2_control/IgnitionSystem</plugin>
        </hardware>
        <joint name="fr_steering_joint">
            <command_interface name="position"/>
            <state_interface name="position"/>
            <state_interface name="velocity"/>
            <state_interface name="effort"/>
        </joint>
        <joint name="fl_steering_joint">
            <command_interface name="position"/>
            <state_interface name="position"/>
            <state_interface name="velocity"/>
            <state_interface name="effort"/>
        </joint>
        <joint name="rr_wheel_joint">
            <command_interface name="velocity"/>
            <state_interface name="position"/>
            <state_interface name="velocity"/>
            <state_interface name="effort"/>
        </joint>
        <joint name="rl_wheel_joint">
            <command_interface name="velocity"/>
            <state_interface name="position"/>
            <state_interface name="velocity"/>
            <state_interface name="effort"/>
        </joint>
    </ros2_control>

    <!-- Gazebo -->
    <gazebo reference="base_link">
        <selfCollide>false</selfCollide>
        <mu1 value="0.5" />
        <mu2 value="0.5" />
    </gazebo>

    <gazebo reference="fr_wheel_link">
        <selfCollide>false</selfCollide>
        <mu1 value="2.0"/>
        <mu2 value="2.0"/>
    </gazebo>

    <gazebo reference="fl_wheel_link">
        <selfCollide>false</selfCollide>
        <mu1 value="2.0"/>
        <mu2 value="2.0"/>
    </gazebo>

    <gazebo reference="rr_wheel_link">
        <selfCollide>false</selfCollide>
        <mu1 value="2.0"/>
        <mu2 value="2.0"/>
    </gazebo>

    <gazebo reference="rl_wheel_link">
        <selfCollide>false</selfCollide>
        <mu1 value="2.0"/>
        <mu2 value="2.0"/>
    </gazebo>


</robot>
